<?xml version="1.0" ?>
<!-- source: https://github.com/RobotnikAutomation/barrett_hand_common/tree/kinetic-devel/barrett_hand_description -->
<!-- =================================================================================== -->
<!-- |    This document was autogenerated by xacro from bh_alone.urdf.xacro            | -->
<!-- |    EDITING THIS FILE BY HAND IS NOT RECOMMENDED                                 | -->
<!-- =================================================================================== -->
<robot name="bhand">
    <!-- HAND WORLD_LINK (RED) -->
    <link name="root">
    <visual>
        <origin xyz="0 0 0"/>
    </visual>
    </link>
    <link name="basex">
        <visual>
            <origin xyz="0 0 0"/>
        </visual>
    </link>
    <link name="basey">
        <visual>
            <origin xyz="0 0 0"/>
        </visual>
    </link>
    <joint name="move_x" type="prismatic">
        <origin rpy="0 0 0" xyz="0.0 0 0.0"/>
        <parent link="root"/>
        <child link="basex"/>
        <axis xyz="1 0 0"/>
        <limit effort="100" lower="-1.5" upper="1.5" velocity="1.0"/>
    </joint>
    <joint name="move_y" type="prismatic">
        <origin rpy="0 0 0" xyz="0.0 0.0 0.0"/>
        <parent link="basex"/>
        <child link="basey"/>
        <axis xyz="0 1 0"/>
        <limit effort="50" lower="-1.5" upper="1.5" velocity="0.3"/>
    </joint>
    <joint name="move_z" type="prismatic">
        <origin rpy="0 0 0" xyz="0.0 0.0 0.0"/>
        <parent link="basey"/>
        <child link="rot_0"/>
        <axis xyz="0 0 1"/>
        <limit effort="50" lower="-1.5" upper="1.5" velocity="0.3"/>
    </joint>
    <link name="rot_0">
        <visual>
            <origin xyz="0 0 0"/>
        </visual>
    </link>
    <link name="rot_1">
        <visual>
            <origin xyz="0 0 0"/>
        </visual>
    </link>
    <link name="rot_2">
        <visual>
            <origin xyz="0 0 0"/>
        </visual>
    </link>

    <joint name="rot_r" type="continuous">
        <origin rpy="0 0 0" xyz="0.0 0.0 0.0"/>
        <parent link="rot_0"/>
        <child link="rot_1"/>
        <axis xyz="1 0 0"/>
    </joint>
    <joint name="rot_p" type="continuous">
        <origin rpy="0 0 0" xyz="0.0 0.0 0.0"/>
        <parent link="rot_1"/>
        <child link="rot_2"/>
        <axis xyz="0 1 0"/>
    </joint>
    <joint name="rot_y" type="continuous">
        <origin rpy="0 0 0" xyz="0.0 0.0 0.0"/>
        <parent link="rot_2"/>
        <child link="bh_base_link"/>
        <axis xyz="0 0 1"/>
    </joint>

    <link name="bh_base_link">
        <inertial>
            <mass value="3.0"/>
            <origin xyz="0 0 0"/>
            <inertia ixx="1.0" ixy="0.0" ixz="0.0" iyy="1.0" iyz="0.0" izz="1.0"/>
        </inertial>
        <visual>
            <origin rpy="0 0 0" xyz="0 0 0"/>
            <geometry>
                <mesh filename="../meshes/palm_282.dae.obj"/>
            </geometry>
            <material name="Grey">
                <color rgba="0.75 0.75 0.75 1.0"/>
            </material>
        </visual>
        <collision>
            <origin rpy="0 0 0 " xyz="0 0 0"/>
            <geometry>
                <mesh filename="../meshes/palm_282.dae.obj"/>
            </geometry>
            <contact_coefficients kd="1.0" kp="1000.0" mu="1000"/>
        </collision>
    </link>
    <!-- finger 3 -->
    <!-- finger 31 link -->
    <link name="bh_finger_31_link">
        <inertial>
            <mass value="0.1"/>
            <origin rpy="0 0 0" xyz="-0.046 0 0"/>
            <inertia ixx="0.01" ixy="0" ixz="0" iyy="0.01" iyz="0" izz="0.01"/>
        </inertial>
        <visual>
            <origin rpy="0 0 0" xyz="-0.04 0 0"/>
            <geometry>
                <mesh filename="../meshes/knuckle_fixed.dae.obj"/>
            </geometry>
            <material name="Black"/>
        </visual>
        <collision>
            <origin rpy="0 0 0" xyz="-0.04 0 0"/>
            <geometry>
                <mesh filename="../meshes/knuckle_fixed.dae.obj"/>
            </geometry>
            <contact_coefficients kd="1.0" kp="1000.0" mu="1000"/>
        </collision>
    </link>
    <!-- joint between BH_palm_link and BH_finger_31_link -->
    <!-- finger3 is the center finger and is fixed -->
    <joint name="bh_j31_joint" type="fixed">
        <parent link="bh_base_link"/>
        <child link="bh_finger_31_link"/>
        <origin rpy="0 0 -1.570796327" xyz="0 0 0.0252"/>
    </joint>
    <!-- finger 32 link -->
    <link name="bh_finger_32_link">
        <inertial>
            <mass value="0.1"/>
            <origin rpy="0 0 0" xyz="0 0 0"/>
            <inertia ixx="0.01" ixy="0" ixz="0" iyy="0.01" iyz="0" izz="0.01"/>
        </inertial>
        <visual>
            <origin rpy="0 0 0" xyz="0 0 0"/>
            <geometry>
                <mesh filename="../meshes/finger.dae.obj"/>
            </geometry>
            <material name="Blue"/>
        </visual>
        <collision>
            <origin rpy="0 0 0" xyz="0 0 0"/>
            <geometry>
                <mesh filename="../meshes/finger.dae.obj"/>
            </geometry>
            <contact_coefficients kd="1.0" kp="1000.0" mu="1000"/>
        </collision>
    </link>
    <!-- joint between BH_finger_31_link and BH_finger_32_link -->
    <joint name="bh_j32_joint" type="revolute">
        <parent link="bh_finger_31_link"/>
        <child link="bh_finger_32_link"/>
        <origin rpy="1.5708 -8.8281E-17 0" xyz="-0.05 0 0.0339"/>
        <axis xyz="0 0 -1"/>
        <limit effort="30.0" lower="0.0" upper="2.44" velocity="2.0"/>
        <dynamics damping="100.0" friction="1.0"/>
    </joint>
    <transmission name="bh_j32_transmission">
        <type>transmission_interface/SimpleTransmission</type>
        <joint name="bh_j32_joint">
            <hardwareInterface>PositionJointInterface</hardwareInterface>
        </joint>
        <actuator name="bh_j32">
            <hardwareInterface>PositionJointInterface</hardwareInterface>
            <mechanicalReduction>1</mechanicalReduction>
            <motorTorqueConstant>1</motorTorqueConstant>
        </actuator>
    </transmission>
    <!-- finger 33 link -->
    <link name="bh_finger_33_link">
        <inertial>
            <mass value="0.1"/>
            <origin rpy="0 0 0" xyz="0 0 0"/>
            <inertia ixx="0.01" ixy="0" ixz="0" iyy="0.01" iyz="0" izz="0.01"/>
        </inertial>
        <visual>
            <origin rpy="0 0 0" xyz="0 0 0"/>
            <geometry>
                <mesh filename="../meshes/finger_tip.dae.obj"/>
            </geometry>
            <material name="Blue"/>
        </visual>
        <collision>
            <origin rpy="0 0 0" xyz="0 0 0"/>
            <geometry>
                <mesh filename="../meshes/finger_tip.dae.obj"/>
            </geometry>
            <contact_coefficients kd="1.0" kp="1000.0" mu="1000"/>
        </collision>
    </link>
    <!-- joint between BH_finger_32_link and BH_finger_33_link -->
    <joint name="bh_j33_joint" type="revolute">
        <parent link="bh_finger_32_link"/>
        <child link="bh_finger_33_link"/>
        <origin rpy="0 0 0" xyz="-0.069936 0.003 0"/>
        <axis xyz="0 0 -1"/>
        <mimic joint="bh_j32_joint" multiplier="0.344262295082"/>
        <limit effort="30.0" lower="0.0" upper="0.84" velocity="2.0"/>
        <dynamics damping="100.0" friction="1.0"/>
    </joint>
    <transmission name="bh_j33_transmission">
        <type>transmission_interface/SimpleTransmission</type>
        <joint name="bh_j33_joint">
            <hardwareInterface>PositionJointInterface</hardwareInterface>
        </joint>
        <actuator name="bh_j33">
            <hardwareInterface>PositionJointInterface</hardwareInterface>
            <mechanicalReduction>1</mechanicalReduction>
            <motorTorqueConstant>1</motorTorqueConstant>
        </actuator>
    </transmission>
    <!-- finger 1 -->
    <!-- finger 11 link -->
    <link name="bh_finger_11_link">
        <inertial>
            <mass value="0.1"/>
            <origin rpy="0 0 0" xyz="-0.046 0 0"/>
            <inertia ixx="0.01" ixy="0" ixz="0" iyy="0.01" iyz="0" izz="0.01"/>
        </inertial>
        <visual>
            <origin rpy="0 0 0" xyz="0 0 0"/>
            <geometry>
                <mesh filename="../meshes/knuckle.dae.obj"/>
            </geometry>
            <material name="Green"/>
        </visual>
        <collision>
            <origin rpy="0 0 0" xyz="0 0 0"/>
            <geometry>
                <mesh filename="../meshes/knuckle.dae.obj"/>
            </geometry>
        </collision>
    </link>
    <!-- joint between BH_palm_link and BH_finger_11_link -->
    <joint name="bh_j11_joint" type="revolute">
        <parent link="bh_base_link"/>
        <child link="bh_finger_11_link"/>
        <origin rpy="0 0 1.5708" xyz="-0.025 0 0.0252"/>
        <axis xyz="0 0 -1"/>
        <limit effort="30.0" lower="0" upper="3.1416" velocity="2.0"/>
        <dynamics damping="100.0" friction="1.0"/>
    </joint>
    <transmission name="bh_j11_transmission">
        <type>transmission_interface/SimpleTransmission</type>
        <joint name="bh_j11_joint">
            <hardwareInterface>PositionJointInterface</hardwareInterface>
        </joint>
        <actuator name="bh_j11">
            <hardwareInterface>PositionJointInterface</hardwareInterface>
            <mechanicalReduction>1</mechanicalReduction>
            <motorTorqueConstant>1</motorTorqueConstant>
        </actuator>
    </transmission>
    <!-- finger 12 link -->
    <link name="bh_finger_12_link">
        <inertial>
            <mass value="0.1"/>
            <origin rpy="0 0 0" xyz="0 0 0"/>
            <inertia ixx="0.01" ixy="0" ixz="0" iyy="0.01" iyz="0" izz="0.01"/>
        </inertial>
        <visual>
            <origin rpy="0 0 0" xyz="0 0 0"/>
            <geometry>
                <mesh filename="../meshes/finger.dae.obj"/>
            </geometry>
            <material name="Blue"/>
        </visual>
        <collision>
            <origin rpy="0 0 0" xyz="0 0 0"/>
            <geometry>
                <mesh filename="../meshes/finger.dae.obj"/>
            </geometry>
            <contact_coefficients kd="1.0" kp="1000.0" mu="1000"/>
        </collision>
    </link>
    <!-- joint between BH_finger_11_link and BH_finger_12_link -->
    <joint name="bh_j12_joint" type="revolute">
        <parent link="bh_finger_11_link"/>
        <child link="bh_finger_12_link"/>
        <origin rpy="1.5708 0 0" xyz="-0.05 0 0.0339"/>
        <axis xyz="0 0 -1"/>
        <limit effort="30.0" lower="0.0" upper="2.44" velocity="2.0"/>
        <dynamics damping="100.0" friction="1.0"/>
    </joint>
    <transmission name="bh_j12_transmission">
        <type>transmission_interface/SimpleTransmission</type>
        <joint name="bh_j12_joint">
            <hardwareInterface>PositionJointInterface</hardwareInterface>
        </joint>
        <actuator name="bh_j12">
            <hardwareInterface>PositionJointInterface</hardwareInterface>
            <mechanicalReduction>1</mechanicalReduction>
            <motorTorqueConstant>1</motorTorqueConstant>
        </actuator>
    </transmission>
    <!-- finger 13 link -->
    <link name="bh_finger_13_link">
        <inertial>
            <mass value="0.1"/>
            <origin rpy="0 0 0" xyz="0 0 0"/>
            <inertia ixx="0.01" ixy="0" ixz="0" iyy="0.01" iyz="0" izz="0.01"/>
        </inertial>
        <visual>
            <origin rpy="0 0 0" xyz="0 0 0"/>
            <geometry>
                <mesh filename="../meshes/finger_tip.dae.obj"/>
            </geometry>
            <material name="Blue"/>
        </visual>
        <collision>
            <origin rpy="0 0 0" xyz="0 0 0"/>
            <geometry>
                <mesh filename="../meshes/finger_tip.dae.obj"/>
            </geometry>
            <contact_coefficients kd="1.0" kp="1000.0" mu="1000"/>
        </collision>
    </link>
    <!-- joint between BH_finger_12_link and BH_finger_13_link -->
    <joint name="bh_j13_joint" type="revolute">
        <parent link="bh_finger_12_link"/>
        <child link="bh_finger_13_link"/>
        <origin rpy="0 0 0" xyz="-0.069936 0.003 0"/>
        <axis xyz="0 0 -1"/>
        <mimic joint="bh_j12_joint" multiplier="0.344262295082"/>
        <limit effort="30.0" lower="0.0" upper="0.84" velocity="2.0"/>
        <dynamics damping="100.0" friction="1.0"/>
    </joint>
    <transmission name="bh_j13_transmission">
        <type>transmission_interface/SimpleTransmission</type>
        <joint name="bh_j13_joint">
            <hardwareInterface>PositionJointInterface</hardwareInterface>
        </joint>
        <actuator name="bh_j13">
            <hardwareInterface>PositionJointInterface</hardwareInterface>
            <mechanicalReduction>1</mechanicalReduction>
            <motorTorqueConstant>1</motorTorqueConstant>
        </actuator>
    </transmission>
    <!-- finger 2 -->
    <!-- finger 21 link -->
    <link name="bh_finger_21_link">
        <inertial>
            <mass value="0.1"/>
            <origin rpy="0 0 0" xyz="-0.046 0 0"/>
            <inertia ixx="0.01" ixy="0" ixz="0" iyy="0.01" iyz="0" izz="0.01"/>
        </inertial>
        <visual>
            <origin rpy="0 0 0" xyz="0 0 0"/>
            <geometry>
                <mesh filename="../meshes/knuckle.dae.obj"/>
            </geometry>
            <material name="Green"/>
        </visual>
        <collision>
            <origin rpy="0 0 0" xyz="0 0 0"/>
            <geometry>
                <mesh filename="../meshes/knuckle.dae.obj"/>
            </geometry>
        </collision>
    </link>
    <!-- joint between BH_palm_link and BH_finger_21_link -->
    <joint name="bh_j21_joint" type="revolute">
        <parent link="bh_base_link"/>
        <child link="bh_finger_21_link"/>
        <origin rpy="0 0 1.5708" xyz="0.025 0 0.0252"/>
        <axis xyz="0 0 1"/>
        <mimic joint="bh_j11_joint" multiplier="1"/>
        <limit effort="30.0" lower="0" upper="3.1416" velocity="2.0"/>
        <dynamics damping="100.0" friction="1.0"/>
    </joint>
    <transmission name="bh_j21_transmission">
        <type>transmission_interface/SimpleTransmission</type>
        <joint name="bh_j21_joint">
            <hardwareInterface>PositionJointInterface</hardwareInterface>
        </joint>
        <actuator name="bh_j21">
            <hardwareInterface>PositionJointInterface</hardwareInterface>
            <mechanicalReduction>1</mechanicalReduction>
            <motorTorqueConstant>1</motorTorqueConstant>
        </actuator>
    </transmission>
    <!-- finger 12 link -->
    <link name="bh_finger_22_link">
        <inertial>
            <mass value="0.1"/>
            <origin rpy="0 0 0" xyz="0 0 0"/>
            <inertia ixx="0.01" ixy="0" ixz="0" iyy="0.01" iyz="0" izz="0.01"/>
        </inertial>
        <visual>
            <origin rpy="0 0 0" xyz="0 0 0"/>
            <geometry>
                <mesh filename="../meshes/finger.dae.obj"/>
            </geometry>
            <material name="Blue"/>
        </visual>
        <collision>
            <origin rpy="0 0 0" xyz="0 0 0"/>
            <geometry>
                <mesh filename="../meshes/finger.dae.obj"/>
            </geometry>
            <contact_coefficients kd="1.0" kp="1000.0" mu="1000"/>
        </collision>
    </link>
    <!-- joint between BH_finger_21_link and BH_finger_22_link -->
    <joint name="bh_j22_joint" type="revolute">
        <parent link="bh_finger_21_link"/>
        <child link="bh_finger_22_link"/>
        <origin rpy="1.5708 -8.8281E-17 0" xyz="-0.05 0 0.0339"/>
        <axis xyz="0 0 -1"/>
        <limit effort="30.0" lower="0.0" upper="2.44" velocity="2.0"/>
        <dynamics damping="100.0" friction="1.0"/>
    </joint>
    <transmission name="bh_j22_transmission">
        <type>transmission_interface/SimpleTransmission</type>
        <joint name="bh_j22_joint">
            <hardwareInterface>PositionJointInterface</hardwareInterface>
        </joint>
        <actuator name="bh_j22">
            <hardwareInterface>PositionJointInterface</hardwareInterface>
            <mechanicalReduction>1</mechanicalReduction>
            <motorTorqueConstant>1</motorTorqueConstant>
        </actuator>
    </transmission>
    <!-- finger 23 link -->
    <link name="bh_finger_23_link">
        <inertial>
            <mass value="0.1"/>
            <origin rpy="0 0 0" xyz="0 0 0"/>
            <inertia ixx="0.01" ixy="0" ixz="0" iyy="0.01" iyz="0" izz="0.01"/>
        </inertial>
        <visual>
            <origin rpy="0 0 0" xyz="0 0 0"/>
            <geometry>
                <mesh filename="../meshes/finger_tip.dae.obj"/>
            </geometry>
            <material name="Blue"/>
        </visual>
        <collision>
            <origin rpy="0 0 0" xyz="0 0 0"/>
            <geometry>
                <mesh filename="../meshes/finger_tip.dae.obj"/>
            </geometry>
            <contact_coefficients kd="1.0" kp="1000.0" mu="1000"/>
        </collision>
    </link>
    <!-- joint between BH_finger_22_link and BH_finger_23_link -->
    <joint name="bh_j23_joint" type="revolute">
        <parent link="bh_finger_22_link"/>
        <child link="bh_finger_23_link"/>
        <origin rpy="0 0 0" xyz="-0.069936 0.003 0"/>
        <axis xyz="0 0 -1"/>
        <mimic joint="bh_j22_joint" multiplier="0.344262295082"/>
        <limit effort="30.0" lower="0.0" upper="0.84" velocity="2.0"/>
        <dynamics damping="100.0" friction="1.0"/>
    </joint>
    <transmission name="bh_j23_transmission">
        <type>transmission_interface/SimpleTransmission</type>
        <joint name="bh_j23_joint">
            <hardwareInterface>PositionJointInterface</hardwareInterface>
        </joint>
        <actuator name="bh_j23">
            <hardwareInterface>PositionJointInterface</hardwareInterface>
            <mechanicalReduction>1</mechanicalReduction>
            <motorTorqueConstant>1</motorTorqueConstant>
        </actuator>
    </transmission>
</robot>

