<?xml version="1.0" ?>
<!-- =================================================================================== -->
<!-- |    This document was autogenerated by xacro from /home/arprice/grasping_ws/src/robotiq_3finger_description/urdf/robotiq_3finger_description.urdf.xacro | -->
<!-- |    EDITING THIS FILE BY HAND IS NOT RECOMMENDED                                 | -->
<!-- =================================================================================== -->
<robot name="victor" xmlns:xacro="http://www.ros.org/wiki/xacro">
  <material name="Black">
    <color rgba="0.0 0.0 0.0 1.0"/>
  </material>
  <material name="Blue">
    <color rgba="0.0 0.0 0.8 1.0"/>
  </material>
  <material name="Green">
    <color rgba="0.0 0.8 0.0 1.0"/>
  </material>
  <material name="Grey">
    <color rgba="0.4 0.4 0.4 1.0"/>
  </material>
  <material name="Orange">
    <color rgba="1.0 0.423529411765 0.0392156862745 1.0"/>
  </material>
  <material name="Brown">
    <color rgba="0.870588235294 0.811764705882 0.764705882353 1.0"/>
  </material>
  <material name="Red">
    <color rgba="0.8 0.0 0.0 1.0"/>
  </material>
  <material name="White">
    <color rgba="1.0 1.0 1.0 1.0"/>
  </material>
  <material name="LightGrey">
    <color rgba="0.7 0.7 0.7 1"/>
  </material>
  <material name="DarkGray">
    <color rgba="0.2 0.2 0.2 1"/>
  </material>
  <material name="DarkDarkGray">
    <color rgba="0.1 0.1 0.1 1"/>
  </material>
  <link name="root">
    <visual>
      <origin xyz="0 0 0"/>
    </visual>
  </link>
  <link name="basex">
    <visual>
      <origin xyz="0 0 0"/>
    </visual>
  </link>
  <link name="basey">
    <visual>
      <origin xyz="0 0 0"/>
    </visual>
  </link>
  <joint name="move_x" type="prismatic">
    <origin rpy="0 0 0" xyz="0.0 0 0.0"/>
    <parent link="root"/>
    <child link="basex"/>
    <axis xyz="1 0 0"/>
    <limit effort="100" lower="-1.5" upper="1.5" velocity="1.0"/>
  </joint>
  <joint name="move_y" type="prismatic">
    <origin rpy="0 0 0" xyz="0.0 0.0 0.0"/>
    <parent link="basex"/>
    <child link="basey"/>
    <axis xyz="0 1 0"/>
    <limit effort="50" lower="-1.5" upper="1.5" velocity="0.3"/>
  </joint>
  <joint name="move_z" type="prismatic">
    <origin rpy="0 0 0" xyz="0.0 0.0 0.0"/>
    <parent link="basey"/>
    <child link="rot_0"/>
    <axis xyz="0 0 1"/>
    <limit effort="50" lower="-1.5" upper="1.5" velocity="0.3"/>
  </joint>
  <link name="rot_0">
    <visual>
      <origin xyz="0 0 0"/>
    </visual>
  </link>
  <link name="rot_1">
    <visual>
      <origin xyz="0 0 0"/>
    </visual>
  </link>
  <link name="rot_2">
    <visual>
      <origin xyz="0 0 0"/>
    </visual>
  </link>

  <joint name="rot_r" type="continuous">
    <origin rpy="0 0 0" xyz="0.0 0.0 0.0"/>
    <parent link="rot_0"/>
    <child link="rot_1"/>
    <axis xyz="1 0 0"/>
  </joint>
  <joint name="rot_p" type="continuous">
    <origin rpy="0 0 0" xyz="0.0 0.0 0.0"/>
    <parent link="rot_1"/>
    <child link="rot_2"/>
    <axis xyz="0 1 0"/>
  </joint>
  <joint name="rot_y" type="continuous">
    <origin rpy="0 0 0" xyz="0.0 0.0 0.0"/>
    <parent link="rot_2"/>
    <child link="palm_base"/>
    <axis xyz="0 0 1"/>
  </joint>

  <link name="palm_base"/>
  <joint name="gripper_palm_joint" type="fixed">
    <origin rpy="0 0 0" xyz="0 0 0"/>
    <parent link="palm_base"/>
    <child link="gripper_palm"/>
  </joint>
  <link name="gripper_palm">
    <inertial>
      <origin rpy="0 0 0" xyz="0 0 0"/>
      <mass value="1"/>
      <inertia ixx="0.01" ixy="0" ixz="0" iyy="0.01" iyz="0" izz="0.01"/>
    </inertial>
    <visual>
      <origin rpy="0 0 0" xyz="0 0 0"/>
      <geometry>
        <mesh filename="../meshes/palm_visual.stl"/>
      </geometry>
      <material name="DarkGray"/>
    </visual>
    <collision>
      <origin rpy="0 0 0" xyz="0 0 0"/>
      <geometry>
        <mesh filename="../meshes/palm_collision.stl"/>
      </geometry>
      <material name="DarkGray"/>
    </collision>
  </link>
  <!-- Palm surface aligned with the gripper axis -->
  <joint name="gripper_palm_surface_joint" type="fixed">
    <parent link="gripper_palm"/>
    <child link="gripper_palm_surface"/>
    <origin rpy="0 0 0" xyz="0 0 0.092075"/>
  </joint>
  <link name="gripper_palm_surface">
        </link>
  <!-- Kuka internal frame has been changed to match our external usage, so identity transform -->
  <joint name="gripper_palm_surface_kuka_joint" type="fixed">
    <parent link="gripper_palm_surface"/>
    <child link="gripper_palm_surface_kuka"/>
    <origin rpy="0 0 0" xyz="0 0 0"/>
  </joint>
  <link name="gripper_palm_surface_kuka">
        </link>
  <!-- Finger A -->
  <joint name="gripper_fingerA_knuckle" type="fixed">
    <origin rpy="0 0 0" xyz="0.02225040 0 0.06111875"/>
    <parent link="gripper_palm"/>
    <child link="gripper_fingerA_base"/>
  </joint>
  <link name="gripper_fingerA_base">
    <inertial>
      <origin rpy="0 0 0" xyz="0 0 0"/>
      <mass value="1"/>
      <inertia ixx="0.01" ixy="0" ixz="0" iyy="0.01" iyz="0" izz="0.01"/>
    </inertial>
    <visual>
      <origin rpy="0 0 0" xyz="0 0 0"/>
      <geometry>
        <mesh filename="../meshes/finger_link1_base_visual.stl"/>
      </geometry>
      <material name="DarkGray"/>
    </visual>
    <collision>
      <origin rpy="0 0 0" xyz="0 0 0"/>
      <geometry>
        <mesh filename="../meshes/finger_link1_base_visual.stl"/>
      </geometry>
      <material name="DarkGray"/>
    </collision>
  </link>
  <!-- Joint 2 (base-prox) -->
  <joint name="gripper_fingerA_joint_2" type="revolute">
    <parent link="gripper_fingerA_base"/>
    <child link="gripper_fingerA_prox"/>
    <origin rpy="0 0.610865238198 0" xyz="0.02225000 0 0.02151380"/>
    <axis xyz="0 1 0"/>
    <limit effort="300" lower="0" upper="1.2217304763960307" velocity="10"/>
    <safety_controller k_position="100" k_velocity="100" soft_lower_limit="-0.610865238198" soft_upper_limit="0.610865238198"/>
    <dynamics damping="0.5"/>
  </joint>
  <link name="gripper_fingerA_prox">
    <inertial>
      <origin rpy="0 0 0" xyz="0 0 0"/>
      <mass value="1"/>
      <inertia ixx="0.01" ixy="0" ixz="0" iyy="0.01" iyz="0" izz="0.01"/>
    </inertial>
    <visual>
      <origin rpy="0 0 0" xyz="0 0 0"/>
      <geometry>
        <mesh filename="../meshes/finger_link2_prox_visual.stl"/>
      </geometry>
      <material name="DarkGray"/>
    </visual>
    <collision>
      <origin rpy="0 0 0" xyz="0 0 0"/>
      <geometry>
        <mesh filename="../meshes/finger_link2_prox_collision.stl"/>
      </geometry>
      <material name="DarkGray"/>
    </collision>
  </link>
  <!-- Joint 3 (prox-med) -->
  <joint name="gripper_fingerA_joint_3" type="revolute">
    <parent link="gripper_fingerA_prox"/>
    <child link="gripper_fingerA_med"/>
    <origin rpy="0 0 0" xyz="0 0 0.05715000"/>
    <axis xyz="0 1 0"/>
    <limit effort="300" lower="-1" upper="1" velocity="10"/>
    <safety_controller k_position="100" k_velocity="100" soft_lower_limit="0.0" soft_upper_limit="1.57079632679"/>
    <dynamics damping="0.5"/>
  </joint>
  <link name="gripper_fingerA_med">
    <inertial>
      <origin rpy="0 0 0" xyz="0 0 0"/>
      <mass value="1"/>
      <inertia ixx="0.01" ixy="0" ixz="0" iyy="0.01" iyz="0" izz="0.01"/>
    </inertial>
    <visual>
      <origin rpy="0 0 0" xyz="0 0 0"/>
      <geometry>
        <mesh filename="../meshes/finger_link3_med_visual.stl"/>
      </geometry>
      <material name="DarkGray"/>
    </visual>
    <collision>
      <origin rpy="0 0 0" xyz="0 0 0"/>
      <geometry>
        <mesh filename="../meshes/finger_link3_med_collision.stl"/>
      </geometry>
      <material name="DarkGray"/>
    </collision>
  </link>
  <!-- Joint 4 (med-dist) -->
  <joint name="gripper_fingerA_joint_4" type="revolute">
    <parent link="gripper_fingerA_med"/>
    <child link="gripper_fingerA_dist"/>
    <origin rpy="0 -0.436332312999 0" xyz="0 0 0.03810000"/>
    <axis xyz="0 1 0"/>
    <limit effort="300" lower="-1" upper="1" velocity="10"/>
    <safety_controller k_position="100" k_velocity="100" soft_lower_limit="-0.436332312999" soft_upper_limit="1.27409035396"/>
    <dynamics damping="0.5"/>
  </joint>
  <link name="gripper_fingerA_dist">
    <inertial>
      <origin rpy="0 0 0" xyz="0 0 0"/>
      <mass value="1"/>
      <inertia ixx="0.01" ixy="0" ixz="0" iyy="0.01" iyz="0" izz="0.01"/>
    </inertial>
    <visual>
      <origin rpy="0 0 0" xyz="0 0 0"/>
      <geometry>
        <mesh filename="../meshes/finger_link4_dist_visual.stl"/>
      </geometry>
      <material name="DarkGray"/>
    </visual>
    <collision>
      <origin rpy="0 0 0" xyz="0 0 0"/>
      <geometry>
        <mesh filename="../meshes/finger_link4_dist_collision.stl"/>
      </geometry>
      <material name="DarkGray"/>
    </collision>
  </link>
  <!-- Finger B -->
  <joint name="gripper_fingerB_knuckle" type="revolute">
    <origin rpy="0 0 3.14159265359" xyz="-0.02230120 0.03651250 0.06111875"/>
    <parent link="gripper_palm"/>
    <child link="gripper_fingerB_base"/>
    <axis xyz="1 0 0"/>
    <limit effort="300" lower="-0.279252680319" upper="0.174532925199" velocity="10"/>
    <safety_controller k_position="100" k_velocity="100" soft_lower_limit="-0.244346095279" soft_upper_limit="0.13962634016"/>
    <dynamics damping="0.5"/>
  </joint>
  <link name="gripper_fingerB_base">
    <inertial>
      <origin rpy="0 0 0" xyz="0 0 0"/>
      <mass value="1"/>
      <inertia ixx="0.01" ixy="0" ixz="0" iyy="0.01" iyz="0" izz="0.01"/>
    </inertial>
    <visual>
      <origin rpy="0 0 0" xyz="0 0 0"/>
      <geometry>
        <mesh filename="../meshes/finger_link1_base_visual.stl"/>
      </geometry>
      <material name="DarkGray"/>
    </visual>
    <collision>
      <origin rpy="0 0 0" xyz="0 0 0"/>
      <geometry>
        <mesh filename="../meshes/finger_link1_base_visual.stl"/>
      </geometry>
      <material name="DarkGray"/>
    </collision>
  </link>
  <!-- Joint 2 (base-prox) -->
  <joint name="gripper_fingerB_joint_2" type="revolute">
    <parent link="gripper_fingerB_base"/>
    <child link="gripper_fingerB_prox"/>
    <origin rpy="0 0.610865238198 0" xyz="0.02225000 0 0.02151380"/>
    <axis xyz="0 1 0"/>
    <limit effort="300" lower="0" upper="1.2217304763960307" velocity="10"/>
    <safety_controller k_position="100" k_velocity="100" soft_lower_limit="-0.610865238198" soft_upper_limit="0.610865238198"/>
    <dynamics damping="0.5"/>
  </joint>
  <link name="gripper_fingerB_prox">
    <inertial>
      <origin rpy="0 0 0" xyz="0 0 0"/>
      <mass value="1"/>
      <inertia ixx="0.01" ixy="0" ixz="0" iyy="0.01" iyz="0" izz="0.01"/>
    </inertial>
    <visual>
      <origin rpy="0 0 0" xyz="0 0 0"/>
      <geometry>
        <mesh filename="../meshes/finger_link2_prox_visual.stl"/>
      </geometry>
      <material name="DarkGray"/>
    </visual>
    <collision>
      <origin rpy="0 0 0" xyz="0 0 0"/>
      <geometry>
        <mesh filename="../meshes/finger_link2_prox_collision.stl"/>
      </geometry>
      <material name="DarkGray"/>
    </collision>
  </link>
  <!-- Joint 3 (prox-med) -->
  <joint name="gripper_fingerB_joint_3" type="revolute">
    <parent link="gripper_fingerB_prox"/>
    <child link="gripper_fingerB_med"/>
    <origin rpy="0 0 0" xyz="0 0 0.05715000"/>
    <axis xyz="0 1 0"/>
    <limit effort="300" lower="-1" upper="1" velocity="10"/>
    <safety_controller k_position="100" k_velocity="100" soft_lower_limit="0.0" soft_upper_limit="1.57079632679"/>
    <dynamics damping="0.5"/>
  </joint>
  <link name="gripper_fingerB_med">
    <inertial>
      <origin rpy="0 0 0" xyz="0 0 0"/>
      <mass value="1"/>
      <inertia ixx="0.01" ixy="0" ixz="0" iyy="0.01" iyz="0" izz="0.01"/>
    </inertial>
    <visual>
      <origin rpy="0 0 0" xyz="0 0 0"/>
      <geometry>
        <mesh filename="../meshes/finger_link3_med_visual.stl"/>
      </geometry>
      <material name="DarkGray"/>
    </visual>
    <collision>
      <origin rpy="0 0 0" xyz="0 0 0"/>
      <geometry>
        <mesh filename="../meshes/finger_link3_med_collision.stl"/>
      </geometry>
      <material name="DarkGray"/>
    </collision>
  </link>
  <!-- Joint 4 (med-dist) -->
  <joint name="gripper_fingerB_joint_4" type="revolute">
    <parent link="gripper_fingerB_med"/>
    <child link="gripper_fingerB_dist"/>
    <origin rpy="0 -0.436332312999 0" xyz="0 0 0.03810000"/>
    <axis xyz="0 1 0"/>
    <limit effort="300" lower="-1" upper="1" velocity="10"/>
    <safety_controller k_position="100" k_velocity="100" soft_lower_limit="-0.436332312999" soft_upper_limit="1.27409035396"/>
    <dynamics damping="0.5"/>
  </joint>
  <link name="gripper_fingerB_dist">
    <inertial>
      <origin rpy="0 0 0" xyz="0 0 0"/>
      <mass value="1"/>
      <inertia ixx="0.01" ixy="0" ixz="0" iyy="0.01" iyz="0" izz="0.01"/>
    </inertial>
    <visual>
      <origin rpy="0 0 0" xyz="0 0 0"/>
      <geometry>
        <mesh filename="../meshes/finger_link4_dist_visual.stl"/>
      </geometry>
      <material name="DarkGray"/>
    </visual>
    <collision>
      <origin rpy="0 0 0" xyz="0 0 0"/>
      <geometry>
        <mesh filename="../meshes/finger_link4_dist_collision.stl"/>
      </geometry>
      <material name="DarkGray"/>
    </collision>
  </link>
  <!-- Finger C -->
  <joint name="gripper_fingerC_knuckle" type="revolute">
    <origin rpy="0 0 3.14159265359" xyz="-0.02230120 -0.03651250 0.06111875"/>
    <parent link="gripper_palm"/>
    <child link="gripper_fingerC_base"/>
    <axis xyz="-1 0 0"/>
    <limit effort="300" lower="-0.279252680319" upper="0.174532925199" velocity="10"/>
    <safety_controller k_position="100" k_velocity="100" soft_lower_limit="-0.244346095279" soft_upper_limit="0.13962634016"/>
    <dynamics damping="0.5"/>
  </joint>
  <link name="gripper_fingerC_base">
    <inertial>
      <origin rpy="0 0 0" xyz="0 0 0"/>
      <mass value="1"/>
      <inertia ixx="0.01" ixy="0" ixz="0" iyy="0.01" iyz="0" izz="0.01"/>
    </inertial>
    <visual>
      <origin rpy="0 0 0" xyz="0 0 0"/>
      <geometry>
        <mesh filename="../meshes/finger_link1_base_visual.stl"/>
      </geometry>
      <material name="DarkGray"/>
    </visual>
    <collision>
      <origin rpy="0 0 0" xyz="0 0 0"/>
      <geometry>
        <mesh filename="../meshes/finger_link1_base_visual.stl"/>
      </geometry>
      <material name="DarkGray"/>
    </collision>
  </link>
  <!-- Joint 2 (base-prox) -->
  <joint name="gripper_fingerC_joint_2" type="revolute">
    <parent link="gripper_fingerC_base"/>
    <child link="gripper_fingerC_prox"/>
    <origin rpy="0 0.610865238198 0" xyz="0.02225000 0 0.02151380"/>
    <axis xyz="0 1 0"/>
    <limit effort="300" lower="0" upper="1.2217304763960307" velocity="10"/>
    <safety_controller k_position="100" k_velocity="100" soft_lower_limit="-0.610865238198" soft_upper_limit="0.610865238198"/>
    <dynamics damping="0.5"/>
  </joint>
  <link name="gripper_fingerC_prox">
    <inertial>
      <origin rpy="0 0 0" xyz="0 0 0"/>
      <mass value="1"/>
      <inertia ixx="0.01" ixy="0" ixz="0" iyy="0.01" iyz="0" izz="0.01"/>
    </inertial>
    <visual>
      <origin rpy="0 0 0" xyz="0 0 0"/>
      <geometry>
        <mesh filename="../meshes/finger_link2_prox_visual.stl"/>
      </geometry>
      <material name="DarkGray"/>
    </visual>
    <collision>
      <origin rpy="0 0 0" xyz="0 0 0"/>
      <geometry>
        <mesh filename="../meshes/finger_link2_prox_collision.stl"/>
      </geometry>
      <material name="DarkGray"/>
    </collision>
  </link>
  <!-- Joint 3 (prox-med) -->
  <joint name="gripper_fingerC_joint_3" type="revolute">
    <parent link="gripper_fingerC_prox"/>
    <child link="gripper_fingerC_med"/>
    <origin rpy="0 0 0" xyz="0 0 0.05715000"/>
    <axis xyz="0 1 0"/>
    <limit effort="300" lower="-1" upper="1" velocity="10"/>
    <safety_controller k_position="100" k_velocity="100" soft_lower_limit="0.0" soft_upper_limit="1.57079632679"/>
    <dynamics damping="0.5"/>
  </joint>
  <link name="gripper_fingerC_med">
    <inertial>
      <origin rpy="0 0 0" xyz="0 0 0"/>
      <mass value="1"/>
      <inertia ixx="0.01" ixy="0" ixz="0" iyy="0.01" iyz="0" izz="0.01"/>
    </inertial>
    <visual>
      <origin rpy="0 0 0" xyz="0 0 0"/>
      <geometry>
        <mesh filename="../meshes/finger_link3_med_visual.stl"/>
      </geometry>
      <material name="DarkGray"/>
    </visual>
    <collision>
      <origin rpy="0 0 0" xyz="0 0 0"/>
      <geometry>
        <mesh filename="../meshes/finger_link3_med_collision.stl"/>
      </geometry>
      <material name="DarkGray"/>
    </collision>
  </link>
  <!-- Joint 4 (med-dist) -->
  <joint name="gripper_fingerC_joint_4" type="revolute">
    <parent link="gripper_fingerC_med"/>
    <child link="gripper_fingerC_dist"/>
    <origin rpy="0 -0.436332312999 0" xyz="0 0 0.03810000"/>
    <axis xyz="0 1 0"/>
    <limit effort="300" lower="-1" upper="1" velocity="10"/>
    <safety_controller k_position="100" k_velocity="100" soft_lower_limit="-0.436332312999" soft_upper_limit="1.27409035396"/>
    <dynamics damping="0.5"/>
  </joint>
  <link name="gripper_fingerC_dist">
    <inertial>
      <origin rpy="0 0 0" xyz="0 0 0"/>
      <mass value="1"/>
      <inertia ixx="0.01" ixy="0" ixz="0" iyy="0.01" iyz="0" izz="0.01"/>
    </inertial>
    <visual>
      <origin rpy="0 0 0" xyz="0 0 0"/>
      <geometry>
        <mesh filename="../meshes/finger_link4_dist_visual.stl"/>
      </geometry>
      <material name="DarkGray"/>
    </visual>
    <collision>
      <origin rpy="0 0 0" xyz="0 0 0"/>
      <geometry>
        <mesh filename="../meshes/finger_link4_dist_collision.stl"/>
      </geometry>
      <material name="DarkGray"/>
    </collision>
  </link>
  <transmission name="gripper_tran_A2">
    <type>transmission_interface/SimpleTransmission</type>
    <joint name="gripper_fingerA_joint_2">
      <hardwareInterface>hardware_interface/EffortJointInterface</hardwareInterface>
    </joint>
    <actuator name="gripper_motor_A2">
      <mechanicalReduction>1</mechanicalReduction>
    </actuator>
  </transmission>
  <transmission name="gripper_tran_A3">
    <type>transmission_interface/SimpleTransmission</type>
    <joint name="gripper_fingerA_joint_3">
      <hardwareInterface>hardware_interface/EffortJointInterface</hardwareInterface>
    </joint>
    <actuator name="gripper_motor_A3">
      <mechanicalReduction>1</mechanicalReduction>
    </actuator>
  </transmission>
  <transmission name="gripper_tran_A4">
    <type>transmission_interface/SimpleTransmission</type>
    <joint name="gripper_fingerA_joint_4">
      <hardwareInterface>hardware_interface/EffortJointInterface</hardwareInterface>
    </joint>
    <actuator name="gripper_motor_A4">
      <mechanicalReduction>1</mechanicalReduction>
    </actuator>
  </transmission>
  <transmission name="gripper_tran_B2">
    <type>transmission_interface/SimpleTransmission</type>
    <joint name="gripper_fingerB_joint_2">
      <hardwareInterface>hardware_interface/EffortJointInterface</hardwareInterface>
    </joint>
    <actuator name="gripper_motor_B2">
      <mechanicalReduction>1</mechanicalReduction>
    </actuator>
  </transmission>
  <transmission name="gripper_tran_B3">
    <type>transmission_interface/SimpleTransmission</type>
    <joint name="gripper_fingerB_joint_3">
      <hardwareInterface>hardware_interface/EffortJointInterface</hardwareInterface>
    </joint>
    <actuator name="gripper_motor_B3">
      <mechanicalReduction>1</mechanicalReduction>
    </actuator>
  </transmission>
  <transmission name="gripper_tran_B4">
    <type>transmission_interface/SimpleTransmission</type>
    <joint name="gripper_fingerB_joint_4">
      <hardwareInterface>hardware_interface/EffortJointInterface</hardwareInterface>
    </joint>
    <actuator name="gripper_motor_B4">
      <mechanicalReduction>1</mechanicalReduction>
    </actuator>
  </transmission>
  <transmission name="gripper_tran_C2">
    <type>transmission_interface/SimpleTransmission</type>
    <joint name="gripper_fingerC_joint_2">
      <hardwareInterface>hardware_interface/EffortJointInterface</hardwareInterface>
    </joint>
    <actuator name="gripper_motor_C2">
      <mechanicalReduction>1</mechanicalReduction>
    </actuator>
  </transmission>
  <transmission name="gripper_tran_C3">
    <type>transmission_interface/SimpleTransmission</type>
    <joint name="gripper_fingerC_joint_3">
      <hardwareInterface>hardware_interface/EffortJointInterface</hardwareInterface>
    </joint>
    <actuator name="gripper_motor_C3">
      <mechanicalReduction>1</mechanicalReduction>
    </actuator>
  </transmission>
  <transmission name="gripper_tran_C4">
    <type>transmission_interface/SimpleTransmission</type>
    <joint name="gripper_fingerC_joint_4">
      <hardwareInterface>hardware_interface/EffortJointInterface</hardwareInterface>
    </joint>
    <actuator name="gripper_motor_C4">
      <mechanicalReduction>1</mechanicalReduction>
    </actuator>
  </transmission>
  <transmission name="gripper_tran_Bknuckle">
    <type>transmission_interface/SimpleTransmission</type>
    <joint name="gripper_fingerB_knuckle">
      <hardwareInterface>hardware_interface/EffortJointInterface</hardwareInterface>
    </joint>
    <actuator name="gripper_motor_Bknuckle">
      <mechanicalReduction>1</mechanicalReduction>
    </actuator>
  </transmission>
  <transmission name="gripper_tran_Cknuckle">
    <type>transmission_interface/SimpleTransmission</type>
    <joint name="gripper_fingerC_knuckle">
      <hardwareInterface>hardware_interface/EffortJointInterface</hardwareInterface>
    </joint>
    <actuator name="gripper_motor_Cknuckle">
      <mechanicalReduction>1</mechanicalReduction>
    </actuator>
  </transmission>
</robot>
