<?xml version="1.0" ?>
<!-- =================================================================================== -->
<!-- |    This document was autogenerated by xacro from urdf/ezgripper_dual_gen2_standalone.urdf.xacro | -->
<!-- |    EDITING THIS FILE BY HAND IS NOT RECOMMENDED                                 | -->
<!-- =================================================================================== -->
<robot xmlns:xacro="http://ros.org/wiki/xacro" name="ezgripper_stand_alone">
  <gazebo>
    <plugin name="gazebo_ros_control" filename="libgazebo_ros_control.so">
   </plugin>
  </gazebo>
  <!-- Add the gripper -->
  <link name="root">
    <visual>
      <origin xyz="0 0 0"/>
    </visual>
  </link>
  <link name="basex">
    <visual>
      <origin xyz="0 0 0"/>
    </visual>
  </link>
  <link name="basey">
    <visual>
      <origin xyz="0 0 0"/>
    </visual>
  </link>
  <joint name="move_x" type="prismatic">
    <origin rpy="0 0 0" xyz="0.0 0 0.0"/>
    <parent link="root"/>
    <child link="basex"/>
    <axis xyz="1 0 0"/>
    <limit effort="100" lower="-1.5" upper="1.5" velocity="1.0"/>
  </joint>
  <joint name="move_y" type="prismatic">
    <origin rpy="0 0 0" xyz="0.0 0.0 0.0"/>
    <parent link="basex"/>
    <child link="basey"/>
    <axis xyz="0 1 0"/>
    <limit effort="50" lower="-1.5" upper="1.5" velocity="0.3"/>
  </joint>
  <joint name="move_z" type="prismatic">
    <origin rpy="0 0 0" xyz="0.0 0.0 0.0"/>
    <parent link="basey"/>
    <child link="rot_0"/>
    <axis xyz="0 0 1"/>
    <limit effort="50" lower="-1.5" upper="1.5" velocity="0.3"/>
  </joint>
  <link name="rot_0">
    <visual>
      <origin xyz="0 0 0"/>
    </visual>
  </link>
  <link name="rot_1">
    <visual>
      <origin xyz="0 0 0"/>
    </visual>
  </link>
  <link name="rot_2">
    <visual>
      <origin xyz="0 0 0"/>
    </visual>
  </link>

  <joint name="rot_r" type="continuous">
    <origin rpy="0 0 0" xyz="0.0 0.0 0.0"/>
    <parent link="rot_0"/>
    <child link="rot_1"/>
    <axis xyz="1 0 0"/>
  </joint>
  <joint name="rot_p" type="continuous">
    <origin rpy="0 0 0" xyz="0.0 0.0 0.0"/>
    <parent link="rot_1"/>
    <child link="rot_2"/>
    <axis xyz="0 1 0"/>
  </joint>
  <joint name="rot_y" type="continuous">
    <origin rpy="0 0 0" xyz="0.0 0.0 0.0"/>
    <parent link="rot_2"/>
    <child link="base_link"/>
    <axis xyz="0 0 1"/>
  </joint>
  <link name="left_ezgripper_palm_link">
    <visual>
      <origin xyz="0 0 0" rpy="0 0 0"/>
      <geometry>
        <mesh filename="../meshes/ezgripper_gen2/SAKE_Palm_Dual_Gen2.stl"/>
      </geometry>
    </visual>
    <collision>
      <origin xyz="0 0 0" rpy="0 0 0"/>
      <geometry>
        <mesh filename="../meshes/ezgripper_gen2/SAKE_Palm_Dual_Gen2.stl"/>
      </geometry>
    </collision>
  </link>
  <joint name="left_ezgripper_connect" type="fixed">
    <origin xyz="0.0 0.0 0.0" rpy="0 0 0"/>
    <!-- <origin rpy="0 0 0" xyz="0.049 0.0 0.2"/> -->
    <parent link="base_link"/>
    <child link="left_ezgripper_palm_link"/>
    <axis xyz="0 0 0"/>
    <limit effort="0" lower="-1.57075" upper="0.25" velocity="3.67"/>
  </joint>
  <link name="left_ezgripper_finger_L1_1">
    <visual>
      <origin xyz="0 0 0" rpy="0 0 0"/>
      <geometry>
        <mesh filename="../meshes/ezgripper_gen2/SAKE_Finger_L1_Gen2.stl"/>
      </geometry>
    </visual>
    <collision>
      <origin xyz="0 0 0" rpy="0 0 0"/>
      <geometry>
        <mesh filename="../meshes/ezgripper_gen2/SAKE_Finger_L1_Gen2.stl"/>
      </geometry>
    </collision>
  </link>
  <link name="left_ezgripper_finger_L1_2">
    <visual>
      <origin xyz="0 0 0" rpy="0 0 0"/>
      <geometry>
        <mesh filename="../meshes/ezgripper_gen2/SAKE_Finger_L1_Gen2.stl"/>
      </geometry>
    </visual>
    <collision>
      <origin xyz="0 0 0" rpy="0 0 0"/>
      <geometry>
        <mesh filename="../meshes/ezgripper_gen2/SAKE_Finger_L1_Gen2.stl"/>
      </geometry>
    </collision>
  </link>
  <link name="left_ezgripper_finger_L2_1">
    <visual>
      <origin xyz="0 0 0" rpy="0 0 0"/>
      <geometry>
        <mesh filename="../meshes/ezgripper_gen2/SAKE_Finger_L2_Gen2.stl"/>
      </geometry>
    </visual>
    <collision>
      <origin xyz="0 0 0" rpy="0 0 0"/>
      <geometry>
        <mesh filename="../meshes/ezgripper_gen2/SAKE_Finger_L2_Gen2.stl"/>
      </geometry>
    </collision>
  </link>
  <link name="left_ezgripper_finger_L2_2">
    <visual>
      <origin xyz="0 0 0" rpy="0 0 0"/>
      <geometry>
        <mesh filename="../meshes/ezgripper_gen2/SAKE_Finger_L2_Gen2.stl"/>
      </geometry>
    </visual>
    <collision>
      <origin xyz="0 0 0" rpy="0 0 0"/>
      <geometry>
        <mesh filename="../meshes/ezgripper_gen2/SAKE_Finger_L2_Gen2.stl"/>
      </geometry>
    </collision>
  </link>
  <joint name="left_ezgripper_knuckle_palm_L1_1" type="revolute">
    <parent link="left_ezgripper_palm_link"/>
    <child link="left_ezgripper_finger_L1_1"/>
    <origin xyz="0.072569 0.03 0" rpy="-1.5708 0 1.57075"/>
    <axis xyz="0 1 0"/>
    <limit lower="0" upper="1.94" effort="1" velocity="3.67"/>
  </joint>
  <joint name="left_ezgripper_knuckle_palm_L1_2" type="revolute">
    <parent link="left_ezgripper_palm_link"/>
    <child link="left_ezgripper_finger_L1_2"/>
    <origin xyz="0.072569 -0.03 0" rpy="1.5708 0 -1.57075"/>
    <axis xyz="0 1 0"/>
    <limit lower="0" upper="1.94" effort="1" velocity="3.67"/>
    <mimic joint="left_ezgripper_knuckle_palm_L1_1"/>
  </joint>
  <joint name="left_ezgripper_knuckle_L1_L2_1" type="revolute">
    <parent link="left_ezgripper_finger_L1_1"/>
    <child link="left_ezgripper_finger_L2_1"/>
    <origin xyz="0.052 0 0" rpy="0 0 0"/>
    <!-- origin xyz="0.06 0 0" rpy="${3.14159 * reflectR} 0 0"/-->
    <axis xyz="0 1 0"/>
    <limit lower="0" upper="1.94" effort="1" velocity="3.67"/>
  </joint>
  <joint name="left_ezgripper_knuckle_L1_L2_2" type="revolute">
    <parent link="left_ezgripper_finger_L1_2"/>
    <child link="left_ezgripper_finger_L2_2"/>
    <origin xyz="0.052 0 0" rpy="0 0 0"/>
    <!-- origin xyz="0.06 0 0" rpy="${3.14159 * reflectR} 0 0"/-->
    <axis xyz="0 1 0"/>
    <limit lower="0" upper="1.94" effort="1" velocity="3.67"/>
    <mimic joint="left_ezgripper_knuckle_L1_L2_1"/>
  </joint>
  <link name="world"/>
  <joint name="fixed" type="fixed">
    <parent link="world"/>
    <origin xyz="0.0 0 0" rpy="0 0 0"/>
    <child link="base_link"/>
  </joint>
  <link name="base_link">
    <visual>
      <geometry>
        <cylinder length="0.42" radius="0.02"/>
      </geometry>
      <origin rpy="0 0 0" xyz="0 0 0.0"/>
      <material name="red"/>
    </visual>
  </link>
</robot>
